Workbook
Name Hoje: TODAY()
Name Hoje: TODAY()
Name Início_da_tarefa: '3 Pessoas'!$E1
Name Início_da_tarefa: 'Planejamento IED'!$C1
Name Início_do_projeto: '3 Pessoas'!$E$3
Name Início_do_projeto: 'Planejamento IED'!#REF!
Name Progresso_da_tarefa: '3 Pessoas'!$D1
Name Progresso_da_tarefa: 'Planejamento IED'!#REF!
Name Semana_de_exibição: '3 Pessoas'!$E$4
Name Semana_de_exibição: 'Planejamento IED'!#REF!
Name Término_da_tarefa: '3 Pessoas'!$F1
Name Término_da_tarefa: 'Planejamento IED'!$D1

Sheet Planejamento IED
A1: Nome | B1: Matrícula | C1: Início | D1: Término | E1: DIAS | F1: Atividade | G1: Detalhamento | H1: Plataforma | I1: Experiência | K1: Campos
A3: JAILTON CONCEIÇÃO | B3: =_xlfn.XLOOKUP(A3,Equipe!H:H,Equipe!B:B,"",0) -> 4612393 | C3: 46209 | D3: 46220 | E3: 12 | F3: Treinamento | G3: Mark Vie GT, Operation & Maintenance | H3: =_xlfn.XLOOKUP(Tabela1[[#This Row],[Matrícula]],Equipe!B:B,Equipe!E:E,"ERRO",0) -> P83 | I3: =VLOOKUP(Tabela1[[#This Row],[Matrícula]],Equipe!B:F,5,0) -> Novo
A4: MARCELO RODRIGUES | B4: =_xlfn.XLOOKUP(A4,Equipe!H:H,Equipe!B:B,"",0) -> 9762281 | C4: 45481 | D4: =((IF(Tabela1[[#This Row],[Início]]<>"",C4+E4-1,""))*1)*1 -> 45501 | E4: 21 | F4: Folga | G4: Folga projetada | H4: =_xlfn.XLOOKUP(Tabela1[[#This Row],[Matrícula]],Equipe!B:B,Equipe!E:E,"ERRO",0) -> P80 | I4: =VLOOKUP(Tabela1[[#This Row],[Matrícula]],Equipe!B:F,5,0) -> Experiente
A5: KEVIN RODRIGUES | B5: =_xlfn.XLOOKUP(A5,Equipe!H:H,Equipe!B:B,"",0) -> 4608544 | C5: 45497 | D5: =((IF(Tabela1[[#This Row],[Início]]<>"",C5+E5-1,""))*1)*1 -> 45508 | E5: 12 | F5: Embarque | G5: Embarque P-48 | H5: =_xlfn.XLOOKUP(Tabela1[[#This Row],[Matrícula]],Equipe!B:B,Equipe!E:E,"ERRO",0) -> P82 | I5: =VLOOKUP(Tabela1[[#This Row],[Matrícula]],Equipe!B:F,5,0) -> Novo
A6: KEVIN RODRIGUES | B6: =_xlfn.XLOOKUP(A6,Equipe!H:H,Equipe!B:B,"",0) -> 4608544 | C6: 45509 | D6: =((IF(Tabela1[[#This Row],[Início]]<>"",C6+E6-1,""))*1)*1 -> 45532 | E6: 24 | F6: Folga | G6: Folga de Embarque | H6: =_xlfn.XLOOKUP(Tabela1[[#This Row],[Matrícula]],Equipe!B:B,Equipe!E:E,"ERRO",0) -> P82 | I6: =VLOOKUP(Tabela1[[#This Row],[Matrícula]],Equipe!B:F,5,0) -> Novo
A7: MARIA CLARA | B7: =_xlfn.XLOOKUP(A7,Equipe!H:H,Equipe!B:B,"",0) -> 4608559 | C7: 45536 | D7: =((IF(Tabela1[[#This Row],[Início]]<>"",C7+E7-1,""))*1)*1 -> 45547 | E7: 12 | F7: Embarque | G7: Embarque P-68 | H7: =_xlfn.XLOOKUP(Tabela1[[#This Row],[Matrícula]],Equipe!B:B,Equipe!E:E,"ERRO",0) -> P83 | I7: =VLOOKUP(Tabela1[[#This Row],[Matrícula]],Equipe!B:F,5,0) -> Novo
A8: MARIA CLARA | B8: =_xlfn.XLOOKUP(A8,Equipe!H:H,Equipe!B:B,"",0) -> 4608559 | C8: 45548 | D8: =((IF(Tabela1[[#This Row],[Início]]<>"",C8+E8-1,""))*1)*1 -> 45573 | E8: 26 | F8: Folga | G8: Folga projetada | H8: =_xlfn.XLOOKUP(Tabela1[[#This Row],[Matrícula]],Equipe!B:B,Equipe!E:E,"ERRO",0) -> P83 | I8: =VLOOKUP(Tabela1[[#This Row],[Matrícula]],Equipe!B:F,5,0) -> Novo
A9: ANDRE STHEL | B9: =_xlfn.XLOOKUP(A9,Equipe!H:H,Equipe!B:B,"",0) -> 4608389 | C9: 45664 | D9: =((IF(Tabela1[[#This Row],[Início]]<>"",C9+E9-1,""))*1)*1 -> 45670 | E9: 7 | F9: Embarque | G9: Embarque P-74 | H9: =_xlfn.XLOOKUP(Tabela1[[#This Row],[Matrícula]],Equipe!B:B,Equipe!E:E,"ERRO",0) -> P80 | I9: =VLOOKUP(Tabela1[[#This Row],[Matrícula]],Equipe!B:F,5,0) -> Novo
A10: ANDRE STHEL | B10: =_xlfn.XLOOKUP(A10,Equipe!H:H,Equipe!B:B,"",0) -> 4608389 | C10: 45671 | D10: =((IF(Tabela1[[#This Row],[Início]]<>"",C10+E10-1,""))*1)*1 -> 45686 | E10: 16 | F10: Folga | G10: Folga projetada | H10: =_xlfn.XLOOKUP(Tabela1[[#This Row],[Matrícula]],Equipe!B:B,Equipe!E:E,"ERRO",0) -> P80 | I10: =VLOOKUP(Tabela1[[#This Row],[Matrícula]],Equipe!B:F,5,0) -> Novo
A11: ANTONIO DANTAS | B11: 1385870 | C11: 45676 | D11: =((IF(Tabela1[[#This Row],[Início]]<>"",C11+E11-1,""))*1)*1 -> 45676 | E11: 1 | F11: Folga | G11: FOLGA NEGOCIADA | H11: =_xlfn.XLOOKUP(Tabela1[[#This Row],[Matrícula]],Equipe!B:B,Equipe!E:E,"ERRO",0) -> P83 | I11: =VLOOKUP(Tabela1[[#This Row],[Matrícula]],Equipe!B:F,5,0) -> Experiente
A12: JOSE LUIS | B12: =_xlfn.XLOOKUP(A12,Equipe!H:H,Equipe!B:B,"",0) | C12: 45676 | D12: =((IF(Tabela1[[#This Row],[Início]]<>"",C12+E12-1,""))*1)*1 -> 45676 | E12: 1 | F12: Folga | G12: FOLGA NEGOCIADA | H12: =_xlfn.XLOOKUP(Tabela1[[#This Row],[Matrícula]],Equipe!B:B,Equipe!E:E,"ERRO",0) -> ERRO | I12: =VLOOKUP(Tabela1[[#This Row],[Matrícula]],Equipe!B:F,5,0) -> #N/A
A13: JUNIO AGOSTINHO | B13: =_xlfn.XLOOKUP(A13,Equipe!H:H,Equipe!B:B,"",0) -> 4608685 | C13: 45721 | D13: =((IF(Tabela1[[#This Row],[Início]]<>"",C13+E13-1,""))*1)*1 -> 45734 | E13: 14 | F13: Embarque | H13: =_xlfn.XLOOKUP(Tabela1[[#This Row],[Matrícula]],Equipe!B:B,Equipe!E:E,"ERRO",0) -> P80 | I13: =VLOOKUP(Tabela1[[#This Row],[Matrícula]],Equipe!B:F,5,0) -> Novo
A14: THIAGO GOMES | B14: =_xlfn.XLOOKUP(A14,Equipe!H:H,Equipe!B:B,"",0) -> 2430855 | C14: 45728 | D14: =((IF(Tabela1[[#This Row],[Início]]<>"",C14+E14-1,""))*1)*1 -> 45730 | E14: 3 | F14: Visita Técnica | H14: =_xlfn.XLOOKUP(Tabela1[[#This Row],[Matrícula]],Equipe!B:B,Equipe!E:E,"ERRO",0) -> PBAC | I14: =VLOOKUP(Tabela1[[#This Row],[Matrícula]],Equipe!B:F,5,0) -> Experiente
A15: VICTOR LÊDO | B15: =_xlfn.XLOOKUP(A15,Equipe!H:H,Equipe!B:B,"",0) -> 9634180 | C15: 45728 | D15: =((IF(Tabela1[[#This Row],[Início]]<>"",C15+E15-1,""))*1)*1 -> 45729 | E15: 2 | F15: Visita Técnica | H15: =_xlfn.XLOOKUP(Tabela1[[#This Row],[Matrícula]],Equipe!B:B,Equipe!E:E,"ERRO",0) -> P83 | I15: =VLOOKUP(Tabela1[[#This Row],[Matrícula]],Equipe!B:F,5,0) -> Experiente
A16: ÁUREO JUNIOR | B16: =_xlfn.XLOOKUP(A16,Equipe!H:H,Equipe!B:B,"",0) -> 1386344 | C16: 45729 | D16: =((IF(Tabela1[[#This Row],[Início]]<>"",C16+E16-1,""))*1)*1 -> 45742 | E16: 14 | F16: Embarque | G16: Embarque P-77 | H16: =_xlfn.XLOOKUP(Tabela1[[#This Row],[Matrícula]],Equipe!B:B,Equipe!E:E,"ERRO",0) -> P82 | I16: =VLOOKUP(Tabela1[[#This Row],[Matrícula]],Equipe!B:F,5,0) -> Experiente
A17: MARCELO RODRIGUES | B17: =_xlfn.XLOOKUP(A17,Equipe!H:H,Equipe!B:B,"",0) -> 9762281 | C17: 45729 | D17: =((IF(Tabela1[[#This Row],[Início]]<>"",C17+E17-1,""))*1)*1 -> 45742 | E17: 14 | F17: Embarque | G17: Embarque P-77 | H17: =_xlfn.XLOOKUP(Tabela1[[#This Row],[Matrícula]],Equipe!B:B,Equipe!E:E,"ERRO",0) -> P80 | I17: =VLOOKUP(Tabela1[[#This Row],[Matrícula]],Equipe!B:F,5,0) -> Experiente
A18: MARIA CLARA | B18: =_xlfn.XLOOKUP(A18,Equipe!H:H,Equipe!B:B,"",0) -> 4608559 | C18: 45733 | D18: =((IF(Tabela1[[#This Row],[Início]]<>"",C18+E18-1,""))*1)*1 -> 45737 | E18: 5 | F18: Treinamento | G18: LM2500 na oficina de turbomáquinas | H18: =_xlfn.XLOOKUP(Tabela1[[#This Row],[Matrícula]],Equipe!B:B,Equipe!E:E,"ERRO",0) -> P83 | I18: =VLOOKUP(Tabela1[[#This Row],[Matrícula]],Equipe!B:F,5,0) -> Novo
A19: ÉDER DOS REIS | B19: =_xlfn.XLOOKUP(A19,Equipe!H:H,Equipe!B:B,"",0) -> 4608474 | C19: 45733 | D19: =((IF(Tabela1[[#This Row],[Início]]<>"",C19+E19-1,""))*1)*1 -> 45737 | E19: 5 | F19: Treinamento | G19: LM2500 na oficina de turbomáquinas | H19: =_xlfn.XLOOKUP(Tabela1[[#This Row],[Matrícula]],Equipe!B:B,Equipe!E:E,"ERRO",0) -> P82 | I19: =VLOOKUP(Tabela1[[#This Row],[Matrícula]],Equipe!B:F,5,0) -> Novo
A20: JORGE HENRIQUE | B20: =_xlfn.XLOOKUP(A20,Equipe!H:H,Equipe!B:B,"",0) -> 9842940 | C20: 45733 | D20: =((IF(Tabela1[[#This Row],[Início]]<>"",C20+E20-1,""))*1)*1 -> 45737 | E20: 5 | F20: Treinamento | G20: LM2500 na oficina de turbomáquinas | H20: =_xlfn.XLOOKUP(Tabela1[[#This Row],[Matrícula]],Equipe!B:B,Equipe!E:E,"ERRO",0) -> P80 | I20: =VLOOKUP(Tabela1[[#This Row],[Matrícula]],Equipe!B:F,5,0) -> Novo
A21: REINALDO MERENDAZ | B21: =_xlfn.XLOOKUP(A21,Equipe!H:H,Equipe!B:B,"",0) -> 4608721 | C21: 45733 | D21: =((IF(Tabela1[[#This Row],[Início]]<>"",C21+E21-1,""))*1)*1 -> 45737 | E21: 5 | F21: Treinamento | G21: LM2500 na oficina de turbomáquinas | H21: =_xlfn.XLOOKUP(Tabela1[[#This Row],[Matrícula]],Equipe!B:B,Equipe!E:E,"ERRO",0) -> P80 | I21: =VLOOKUP(Tabela1[[#This Row],[Matrícula]],Equipe!B:F,5,0) -> Novo
A22: JUNIO AGOSTINHO | B22: =_xlfn.XLOOKUP(A22,Equipe!H:H,Equipe!B:B,"",0) -> 4608685 | C22: 45735 | D22: =((IF(Tabela1[[#This Row],[Início]]<>"",C22+E22-1,""))*1)*1 -> 45763 | E22: 29 | F22: Folga | G22: Folga projetada | H22: =_xlfn.XLOOKUP(Tabela1[[#This Row],[Matrícula]],Equipe!B:B,Equipe!E:E,"ERRO",0) -> P80 | I22: =VLOOKUP(Tabela1[[#This Row],[Matrícula]],Equipe!B:F,5,0) -> Novo
A23: FELIPE CAHET | B23: =_xlfn.XLOOKUP(A23,Equipe!H:H,Equipe!B:B,"",0) -> 2493288 | C23: 45740 | D23: =((IF(Tabela1[[#This Row],[Início]]<>"",C23+E23-1,""))*1)*1 -> 45741 | E23: 2 | F23: Folga | H23: =_xlfn.XLOOKUP(Tabela1[[#This Row],[Matrícula]],Equipe!B:B,Equipe!E:E,"ERRO",0) -> PBAC | I23: =VLOOKUP(Tabela1[[#This Row],[Matrícula]],Equipe!B:F,5,0) -> Experiente
A24: ÁUREO JUNIOR | B24: =_xlfn.XLOOKUP(A24,Equipe!H:H,Equipe!B:B,"",0) -> 1386344 | C24: 45743 | D24: =((IF(Tabela1[[#This Row],[Início]]<>"",C24+E24-1,""))*1)*1 -> 45763 | E24: 21 | F24: Folga | G24: Folga projetada | H24: =_xlfn.XLOOKUP(Tabela1[[#This Row],[Matrícula]],Equipe!B:B,Equipe!E:E,"ERRO",0) -> P82 | I24: =VLOOKUP(Tabela1[[#This Row],[Matrícula]],Equipe!B:F,5,0) -> Experiente
A25: IGOR TEIXEIRA | B25: =_xlfn.XLOOKUP(A25,Equipe!H:H,Equipe!B:B,"",0) -> 1385894 | C25: 45743 | D25: =((IF(Tabela1[[#This Row],[Início]]<>"",C25+E25-1,""))*1)*1 -> 45743 | E25: 1 | F25: Treinamento | H25: =_xlfn.XLOOKUP(Tabela1[[#This Row],[Matrícula]],Equipe!B:B,Equipe!E:E,"ERRO",0) -> P80 | I25: =VLOOKUP(Tabela1[[#This Row],[Matrícula]],Equipe!B:F,5,0) -> Experiente
A26: KEVIN RODRIGUES | B26: =_xlfn.XLOOKUP(A26,Equipe!H:H,Equipe!B:B,"",0) -> 4608544 | C26: 45743 | D26: =((IF(Tabela1[[#This Row],[Início]]<>"",C26+E26-1,""))*1)*1 -> 45744 | E26: 2 | F26: Folga | G26: Redução MB | H26: =_xlfn.XLOOKUP(Tabela1[[#This Row],[Matrícula]],Equipe!B:B,Equipe!E:E,"ERRO",0) -> P82 | I26: =VLOOKUP(Tabela1[[#This Row],[Matrícula]],Equipe!B:F,5,0) -> Novo
A27: MARCELO RODRIGUES | B27: =_xlfn.XLOOKUP(A27,Equipe!H:H,Equipe!B:B,"",0) -> 9762281 | C27: 45743 | D27: 45763 | E27: 21 | F27: Folga | G27: Folga projetada | H27: =_xlfn.XLOOKUP(Tabela1[[#This Row],[Matrícula]],Equipe!B:B,Equipe!E:E,"ERRO",0) -> P80 | I27: =VLOOKUP(Tabela1[[#This Row],[Matrícula]],Equipe!B:F,5,0) -> Experiente
A28: ANDRÉ LARANGEIRA | B28: =_xlfn.XLOOKUP(A28,Equipe!H:H,Equipe!B:B,"",0) -> 9724817 | C28: 45748 | D28: =((IF(Tabela1[[#This Row],[Início]]<>"",C28+E28-1,""))*1)*1 -> 45758 | E28: 11 | F28: Embarque | G28: Embarque P-75 + compra da folga projetada CC CGM MIED BÚZIOS ER69SMMA45 | H28: =_xlfn.XLOOKUP(Tabela1[[#This Row],[Matrícula]],Equipe!B:B,Equipe!E:E,"ERRO",0) -> P82 | I28: =VLOOKUP(Tabela1[[#This Row],[Matrícula]],Equipe!B:F,5,0) -> Experiente
A29: RAFAEL LUSQUINOS | B29: =_xlfn.XLOOKUP(A29,Equipe!H:H,Equipe!B:B,"",0) -> 9634222 | C29: 45754 | D29: =((IF(Tabela1[[#This Row],[Início]]<>"",C29+E29-1,""))*1)*1 -> 45758 | E29: 5 | F29: Treinamento | G29: CBSP | H29: =_xlfn.XLOOKUP(Tabela1[[#This Row],[Matrícula]],Equipe!B:B,Equipe!E:E,"ERRO",0) -> P83 | I29: =VLOOKUP(Tabela1[[#This Row],[Matrícula]],Equipe!B:F,5,0) -> Experiente
A30: TADEU MENEGUSSI | B30: =_xlfn.XLOOKUP(A30,Equipe!H:H,Equipe!B:B,"",0) -> 1381625 | C30: 45754 | D30: =((IF(Tabela1[[#This Row],[Início]]<>"",C30+E30-1,""))*1)*1 -> 45758 | E30: 5 | F30: Embarque | G30: Embarque P-77 ,compra da folga projetada CC: CGM MIED BÚZIOS ER69SMMA45 | H30: =_xlfn.XLOOKUP(Tabela1[[#This Row],[Matrícula]],Equipe!B:B,Equipe!E:E,"ERRO",0) -> P80 | I30: =VLOOKUP(Tabela1[[#This Row],[Matrícula]],Equipe!B:F,5,0) -> Experiente
A31: ANTONIO RAFAEL | B31: =_xlfn.XLOOKUP(A31,Equipe!H:H,Equipe!B:B,"",0) -> 4608411 | C31: 45756 | D31: =((IF(Tabela1[[#This Row],[Início]]<>"",C31+E31-1,""))*1)*1 -> 45756 | E31: 1 | F31: Workshop | G31: Apresentação SLO - Injection | H31: =_xlfn.XLOOKUP(Tabela1[[#This Row],[Matrícula]],Equipe!B:B,Equipe!E:E,"ERRO",0) -> P83 | I31: =VLOOKUP(Tabela1[[#This Row],[Matrícula]],Equipe!B:F,5,0) -> Novo
A32: ÉDER DOS REIS | B32: =_xlfn.XLOOKUP(A32,Equipe!H:H,Equipe!B:B,"",0) -> 4608474 | C32: 45756 | D32: =((IF(Tabela1[[#This Row],[Início]]<>"",C32+E32-1,""))*1)*1 -> 45756 | E32: 1 | F32: Workshop | G32: Apresentação Gás de processo - MAIN PBAC | H32: =_xlfn.XLOOKUP(Tabela1[[#This Row],[Matrícula]],Equipe!B:B,Equipe!E:E,"ERRO",0) -> P82 | I32: =VLOOKUP(Tabela1[[#This Row],[Matrícula]],Equipe!B:F,5,0) -> Novo
A33: FABIO CAMILO | B33: =_xlfn.XLOOKUP(A33,Equipe!H:H,Equipe!B:B,"",0) -> 4606694 | C33: 45756 | D33: =((IF(Tabela1[[#This Row],[Início]]<>"",C33+E33-1,""))*1)*1 -> 45756 | E33: 1 | F33: Treinamento | G33: Requisitante PT | H33: =_xlfn.XLOOKUP(Tabela1[[#This Row],[Matrícula]],Equipe!B:B,Equipe!E:E,"ERRO",0) -> PBAC | I33: =VLOOKUP(Tabela1[[#This Row],[Matrícula]],Equipe!B:F,5,0) -> Novo
A34: KEVIN RODRIGUES | B34: =_xlfn.XLOOKUP(A34,Equipe!H:H,Equipe!B:B,"",0) -> 4608544 | C34: 45756 | D34: =((IF(Tabela1[[#This Row],[Início]]<>"",C34+E34-1,""))*1)*1 -> 45756 | E34: 1 | F34: Workshop | G34: Apresentação sobre o Processo do GAS INJECTION (1252) no PBAC | H34: =_xlfn.XLOOKUP(Tabela1[[#This Row],[Matrícula]],Equipe!B:B,Equipe!E:E,"ERRO",0) -> P82 | I34: =VLOOKUP(Tabela1[[#This Row],[Matrícula]],Equipe!B:F,5,0) -> Novo
A35: RAFAEL VENTURINI | B35: =_xlfn.XLOOKUP(A35,Equipe!H:H,Equipe!B:B,"",0) -> 4608780 | C35: 45756 | D35: =((IF(Tabela1[[#This Row],[Início]]<>"",C35+E35-1,""))*1)*1 -> 45756 | E35: 1 | F35: Workshop | G35: Apresentação Main - WO & LO | H35: =_xlfn.XLOOKUP(Tabela1[[#This Row],[Matrícula]],Equipe!B:B,Equipe!E:E,"ERRO",0) -> P83 | I35: =VLOOKUP(Tabela1[[#This Row],[Matrícula]],Equipe!B:F,5,0) -> Novo
A36: ANTONIO RAFAEL | B36: =_xlfn.XLOOKUP(A36,Equipe!H:H,Equipe!B:B,"",0) -> 4608411 | C36: 45757 | D36: =((IF(Tabela1[[#This Row],[Início]]<>"",C36+E36-1,""))*1)*1 -> 45758 | E36: 2 | F36: Folga | G36: Necessidade pessoal | H36: =_xlfn.XLOOKUP(Tabela1[[#This Row],[Matrícula]],Equipe!B:B,Equipe!E:E,"ERRO",0) -> P83 | I36: =VLOOKUP(Tabela1[[#This Row],[Matrícula]],Equipe!B:F,5,0) -> Novo
A37: ALEXSANDRO VIANA | B37: =_xlfn.XLOOKUP(A37,Equipe!H:H,Equipe!B:B,"",0) -> 2477135 | C37: 45761 | D37: =((IF(Tabela1[[#This Row],[Início]]<>"",C37+E37-1,""))*1)*1 -> 45761 | E37: 1 | F37: Workshop | H37: =_xlfn.XLOOKUP(Tabela1[[#This Row],[Matrícula]],Equipe!B:B,Equipe!E:E,"ERRO",0) -> P83 | I37: =VLOOKUP(Tabela1[[#This Row],[Matrícula]],Equipe!B:F,5,0) -> Experiente
A38: JULIO CESAR FASSARELA | B38: =_xlfn.XLOOKUP(A38,Equipe!H:H,Equipe!B:B,"",0) -> 4608684 | C38: 45761 | D38: =((IF(Tabela1[[#This Row],[Início]]<>"",C38+E38-1,""))*1)*1 -> 45761 | E38: 1 | F38: Workshop | H38: =_xlfn.XLOOKUP(Tabela1[[#This Row],[Matrícula]],Equipe!B:B,Equipe!E:E,"ERRO",0) -> P82 | I38: =VLOOKUP(Tabela1[[#This Row],[Matrícula]],Equipe!B:F,5,0) -> Novo
A39: FELIPE CAHET | B39: =_xlfn.XLOOKUP(A39,Equipe!H:H,Equipe!B:B,"",0) -> 2493288 | C39: 45769 | D39: =((IF(Tabela1[[#This Row],[Início]]<>"",C39+E39-1,""))*1)*1 -> 45769 | E39: 1 | F39: Folga | G39: Redução MB | H39: =_xlfn.XLOOKUP(Tabela1[[#This Row],[Matrícula]],Equipe!B:B,Equipe!E:E,"ERRO",0) -> PBAC | I39: =VLOOKUP(Tabela1[[#This Row],[Matrícula]],Equipe!B:F,5,0) -> Experiente
A40: ANDERSON JOSÉ | B40: =_xlfn.XLOOKUP(A40,Equipe!H:H,Equipe!B:B,"",0) -> 9612082 | C40: 45770 | D40: =((IF(Tabela1[[#This Row],[Início]]<>"",C40+E40-1,""))*1)*1 -> 45780 | E40: 11 | F40: Embarque | G40: Apoi técnico de execução na parada VRU, TC e TG, na P-76 | H40: =_xlfn.XLOOKUP(Tabela1[[#This Row],[Matrícula]],Equipe!B:B,Equipe!E:E,"ERRO",0) -> P82 | I40: =VLOOKUP(Tabela1[[#This Row],[Matrícula]],Equipe!B:F,5,0) -> Experiente
A41: IGOR TEIXEIRA | B41: =_xlfn.XLOOKUP(A41,Equipe!H:H,Equipe!B:B,"",0) -> 1385894 | C41: 45770 | D41: =((IF(Tabela1[[#This Row],[Início]]<>"",C41+E41-1,""))*1)*1 -> 45777 | E41: 8 | F41: Embarque | G41: Embarque P-76 + Folga projetada | H41: =_xlfn.XLOOKUP(Tabela1[[#This Row],[Matrícula]],Equipe!B:B,Equipe!E:E,"ERRO",0) -> P80 | I41: =VLOOKUP(Tabela1[[#This Row],[Matrícula]],Equipe!B:F,5,0) -> Experiente
...

Sheet Homero
A1: Disciplina | B1: Matrícula | C1: Chave | D1: Função | E1: Projeto | F1: Experiência | G1: Profissional | H1: E-mail | I1: Status | J1: Turma
A2: ELET | B2: 4612171 | C2: FWB5 | D2: Técnico | E2: P80 | F2: Novo | G2: TONICLER KUTZ | H2: tonicler.kutz@petrobras.com.br | I2: Pendente | J2: 46296
A3: ELET | B3: 4612050 | C3: FW66 | D3: Técnico | E3: P82 | F3: Novo | G3: LUIZ FERNANDO | H3: luiz.ramos3@petrobras.com.br | I3: Pendente | J3: 46174
A4: ELET | B4: 4612140 | C4: FVVS | D4: Técnico | E4: P83 | F4: Novo | G4: BRENO CARVALHO | H4: breno.batista@petrobras.com.br | I4: Pendente | J4: 46296
A5: MEC | B5: 4608389 | C5: F9U6 | D5: Técnico | E5: P80 | F5: Novo | G5: ANDRE STHEL | H5: andre.sthel@petrobras.com.br | I5: Pendente | J5: 46296
A6: MEC | B6: 4612098 | C6: FW44 | D6: Técnico | E6: P80 | F6: Novo | G6: ANDRE SILVA | H6: andre.silva35@petrobras.com.br | I6: Pendente | J6: 46235
A7: MEC | B7: 4612126 | C7: FW52 | D7: Técnico | E7: P82 | F7: Novo | G7: THIELLES GUSTAVO | H7: thielles.gustavo@petrobras.com.br | I7: Realizado | J7: -
A8: MEC | B8: 4613176 | C8: G7OU | D8: Técnico | E8: P82 | F8: Novo | G8: FILIPI MARQUEZINE | H8: filipi.pinto@petrobras.com.br | I8: Pendente | J8: 46235
A9: MEC | B9: 4613186 | C9: G7PT | D9: Técnico | E9: P83 | F9: Novo | G9: EDISON NOVAES | H9: edison.amaral@petrobras.com.br | I9: Pendente | J9: 46296
A10: INST | B10: 4612243 | C10: FWCC | D10: Técnico | E10: P80 | F10: Novo | G10: PABLO ALMEIDA | H10: pablo.p.almeida@petrobras.com.br | I10: Pendente | J10: 46174
A11: INST | B11: 4612389 | C11: FVX0 | D11: Técnico | E11: P80 | F11: Novo | G11: RONALD QUARESMA | H11: ronald.quaresma@petrobras.com.br | I11: Pendente | J11: 46235
A12: INST | B12: 4612192 | C12: FVV0 | D12: Técnico | E12: P82 | F12: Novo | G12: VICTOR CAMPOS | H12: victor.f.campos@petrobras.com.br | I12: Pendente | J12: 46296
A13: INST | B13: 4612393 | C13: FVWH | D13: Técnico | E13: P83 | F13: Novo | G13: JAILTON CONCEIÇÃO | H13: jailton.conceicao@petrobras.com.br | I13: Pendente | J13: 46296
A14: INST | B14: 4612228 | C14: FWNL | D14: Técnico | E14: P82 | F14: Novo | G14: LUIZ SERPA | H14: luiz.serpa@petrobras.com.br | I14: Pendente | J14: 46174
A15: INST | B15: 4612247 | C15: FW96 | D15: Técnico | E15: P83 | F15: Novo | G15: RICARDO UEMA | H15: ricardo.uema@petrobras.com.br | I15: Pendente | J15: 46174
A16: INST | B16: 1385950 | C16: URCQ | D16: Técnico | E16: P82 | F16: Experiente | G16: ALEXANDRE MARTINS | H16: alexandre.martins@petrobras.com.br | I16: Dispensado | J16: -
A17: INST | B17: 1387328 | C17: LMJ5 | D17: Técnico | E17: P82 | F17: Experiente | G17: ANDERSON COUTINHO | H17: acrodrig@petrobras.com.br | I17: Pendente | J17: 46296
A18: INST | B18: 1385870 | C18: URCU | D18: Técnico | E18: P83 | F18: Experiente | G18: ANTONIO DANTAS | H18: acdantas@petrobras.com.br | I18: Pendente | J18: 46235
A19: INST | B19: 1386288 | C19: UREM | D19: Técnico | E19: P83 | F19: Experiente | G19: AURELIO RODRIGUES | H19: aureliorv@petrobras.com.br | I19: Pendente | J19: 46174
A20: INST | B20: 9678697 | C20: WUXI | D20: Técnico | E20: P80 | F20: Experiente | G20: JOSE LUIS | H20: jluiscruz@petrobras.com.br | I20: Pendente | J20: 46296
A21: ELET | B21: 9921954 | C21: RH5O | D21: Técnico | E21: P82 | F21: Experiente | G21: FREDERICO AUGUSTO | H21: fredericoaugusto@petrobras.com.br | I21: Pendente | J21: 46174
A22: ELET | B22: 2448533 | C22: N7SC | D22: Técnico | E22: P80 | F22: Experiente | G22: RODRIGO SCORALICK | H22: rodrigosfn@petrobras.com.br | I22: Pendente | J22: 46235
A23: MEC | B23: 2477135 | C23: PL7T | D23: Técnico | E23: P83 | F23: Experiente | G23: ALEXSANDRO VIANA | H23: alexsandroviana@petrobras.com.br | I23: Pendente | J23: 46296
A24: MEC | B24: 9612082 | C24: FRBT | D24: Técnico | E24: P82 | F24: Experiente | G24: ANDERSON JOSÉ | H24: andi9@petrobras.com.br | I24: Pendente | J24: 46174
A25: MEC | B25: 2440812 | C25: KI7N | D25: Supervisor | E25: P80 | F25: Experiente | G25: MARCIO AMARAL | H25: marcioamaral@petrobras.com.br | I25: Pendente | J25: 46296

Sheet Equipe
A1: Disciplina | B1: Matrícula | C1: Chave | D1: Função | E1: Projeto | F1: Experiência | G1: E-mail | H1: Nome | I1: Escalado Angra? | J1: EP
A2: ELET | B2: 4612171 | C2: FWB5 | D2: Técnico | E2: P80 | F2: Novo | G2: tonicler.kutz@petrobras.com.br | H2: TONICLER KUTZ | I2: Planejar
A3: ELET | B3: 4612050 | C3: FW66 | D3: Técnico | E3: P82 | F3: Novo | G3: luiz.ramos3@petrobras.com.br | H3: LUIZ FERNANDO | I3: X
A4: ELET | B4: 4612140 | C4: FVVS | D4: Técnico | E4: P83 | F4: Novo | G4: breno.batista@petrobras.com.br | H4: BRENO CARVALHO | I4: Planejar
A5: ELET | B5: 9842940 | C5: HFO8 | D5: Técnico | E5: P80 | F5: Novo | G5: jorge.mariano@petrobras.com.br | H5: JORGE HENRIQUE
A6: INST | B6: 9886449 | C6: APDZ | D6: Técnico | E6: P80 | F6: Experiente | G6: er.amaral@petrobras.com.br | H6: EDUARDO RIBEIRO | I6: X | J6: EMITIDO 29/12/2025
A7: INST | B7: 4608721 | C7: F9TE | D7: Técnico | E7: P80 | F7: Novo | G7: reinaldo.merendaz@petrobras.com.br | H7: REINALDO MERENDAZ | I7: X
A8: INST | B8: 1385894 | C8: URDD | D8: Técnico | E8: P80 | F8: Experiente | G8: igorteixeira@petrobras.com.br | H8: IGOR TEIXEIRA | I8: X | J8: PLANEJAR
A9: INST | B9: 4608685 | C9: F9XJ | D9: Técnico | E9: P80 | F9: Novo | G9: junio.matos@petrobras.com.br | H9: JUNIO AGOSTINHO | I9: X
A10: MEC | B10: 9762281 | C10: MGKN | D10: Técnico | E10: P80 | F10: Experiente | G10: marsantos@petrobras.com.br | H10: MARCELO RODRIGUES | I10: X | J10: EMITIDO EM 09/01/2026 (1 ANO)
A11: MEC | B11: 9683150 | C11: JGYW | D11: Técnico | E11: P80 | F11: Experiente | G11: flaviomarinho@petrobras.com.br | H11: FLÁVIO MARINHO | I11: X | J11: PEDIDO
A12: MEC | B12: 2440812 | C12: KI7N | D12: Supervisor | E12: P80 | F12: Experiente | G12: marcioamaral@petrobras.com.br | H12: MARCIO AMARAL | I12: X
A13: MEC | B13: 1381625 | C13: URBI | D13: Técnico | E13: P80 | F13: Experiente | G13: tmenegussi@petrobras.com.br | H13: TADEU MENEGUSSI | I13: X
A14: MEC | B14: 4608389 | C14: F9U6 | D14: Técnico | E14: P80 | F14: Novo | G14: andre.sthel@petrobras.com.br | H14: ANDRE STHEL | I14: X
A15: ELET | B15: 4608544 | C15: F9TG | D15: Técnico | E15: P82 | F15: Novo | G15: kevin.cunha@petrobras.com.br | H15: KEVIN RODRIGUES | I15: X
A16: INST | B16: 4608474 | C16: F9NN | D16: Técnico | E16: P82 | F16: Novo | G16: eder.reis@petrobras.com.br | H16: ÉDER DOS REIS | I16: X
A17: INST | B17: 1386344 | C17: URCX | D17: Técnico | E17: P82 | F17: Experiente | G17: aureojr@petrobras.com.br | H17: ÁUREO JUNIOR | I17: X | J17: PEDIDO
A18: INST | B18: 4608684 | C18: F9YD | D18: Técnico | E18: P82 | F18: Novo | G18: julio.fassarela@petrobras.com.br | H18: JULIO CESAR FASSARELA | I18: X
A19: MEC | B19: 9612082 | C19: FRBT | D19: Técnico | E19: P82 | F19: Experiente | G19: andi9@petrobras.com.br | H19: ANDERSON JOSÉ | I19: X
A20: MEC | B20: 9618720 | C20: URIY | D20: Técnico | E20: P82 | F20: Experiente | G20: diogosouza@petrobras.com.br | H20: DIOGO FRAZÃO | I20: X | J20: PLANEJAR
A21: MEC | B21: 9724817 | C21: RTB3 | D21: Técnico | E21: P82 | F21: Experiente | G21: al.larangeira@petrobras.com.br | H21: ANDRÉ LARANGEIRA | I21: X
A22: MEC | B22: 2460800 | C22: N7G6 | D22: Supervisor | E22: P82 | F22: Experiente | G22: wellingtonmarques@petrobras.com.br | H22: WELLINGTON MARQUES
A23: ELET | B23: 4608559 | C23: F9RL | D23: Técnico | E23: P83 | F23: Novo | G23: maria.santos8@petrobras.com.br | H23: MARIA CLARA | I23: X
A24: INST | B24: 4608411 | C24: F9N8 | D24: Técnico | E24: P83 | F24: Novo | G24: antonio.r.cunha@petrobras.com.br | H24: ANTONIO RAFAEL | I24: X
A25: INST | B25: 9634180 | C25: URMC | D25: Técnico | E25: P83 | F25: Experiente | G25: vledo@petrobras.com.br | H25: VICTOR LÊDO | I25: X
A26: MEC | B26: 4608780 | C26: EMRV | D26: Técnico | E26: P83 | F26: Novo | G26: rafaelventurini@petrobras.com.br | H26: RAFAEL VENTURINI | I26: X
A27: MEC | B27: 2475130 | C27: N6AT | D27: Técnico | E27: P83 | F27: Experiente | G27: raulalende@petrobras.com.br | H27: RAUL ALENDE | J27: EMITIDO 26/11/2025
A28: MEC | B28: 2477135 | C28: PL7T | D28: Técnico | E28: P83 | F28: Experiente | G28: alexsandroviana@petrobras.com.br | H28: ALEXSANDRO VIANA | I28: X
A29: ELET | B29: 4606246 | C29: EVPY | D29: Engenheiro | E29: PBAC | F29: Novo | G29: julio.bento@petrobras.com.br | H29: JULIO CESAR BENTO | I29: X
A30: INST | B30: 4606308 | C30: EVIY | D30: Engenheiro | E30: PBAC | F30: Novo | G30: pietro.konzgen@petrobras.com.br | H30: PIETRO SERPA
A31: INST | B31: 9634222 | C31: URME | D31: Técnico | E31: P83 | F31: Experiente | G31: rperez@petrobras.com.br | H31: RAFAEL LUSQUINOS | I31: X | J31: PEDIDO
A32: INST | B32: 229316 | C32: CLWA | D32: Engenheiro | E32: PBAC | F32: Experiente | G32: leandro.eloy@petrobras.com.br | H32: LEANDRO ELOY | I32: X
A33: MEC | B33: 2493288 | C33: HR64 | D33: Engenheiro | E33: PBAC | F33: Experiente | G33: felipecahet@petrobras.com.br | H33: FELIPE CAHET | I33: X
A34: MEC | B34: 214272 | C34: CTNR | D34: Engenheiro | E34: PBAC | F34: Experiente | G34: marcelo.vaqueiro@petrobras.com.br | H34: MARCELO VAQUEIRO | I34: X
A35: MEC | B35: 4606694 | C35: F0I7 | D35: Engenheiro | E35: PBAC | F35: Novo | G35: fabio.unterman@petrobras.com.br | H35: FABIO CAMILO
A36: MEC | B36: 2430855 | C36: R29L | D36: Técnico | E36: PBAC | F36: Experiente | G36: thiago_gomes@petrobras.com.br | H36: THIAGO GOMES | I36: X
A37: MEC | B37: 4604625 | C37: DVPX | D37: Coordenador | E37: PBAC | F37: Novo | G37: vinicius.s.duarte@petrobras.com.br | H37: VINICIUS DUARTE | I37: X
A38: MEC | B38: 4612098 | C38: FW44 | D38: Técnico | E38: P80 | F38: Novo | G38: andre.silva35@petrobras.com.br | H38: ANDRE SILVA | I38: X
A39: MEC | B39: 4612126 | C39: FW52 | D39: Técnico | E39: P82 | F39: Novo | G39: thielles.gustavo@petrobras.com.br | H39: THIELLES GUSTAVO | I39: X
A40: MEC | B40: 2550195 | C40: N70D | D40: Supervisor | E40: P83 | F40: Experiente | G40: dimitriaraujo@petrobras.com.br | H40: DIMITRI ARAUJO
...

Sheet Embarques Vivenciais
B2: Geral | I2: P80 | P2: P82 | W2: P83 | AJ2: Até hoje | AL2: Hoje+Programados
B3: Data | C3: Data | D3: Embarques | E3: Necessidade | F3: Dias | G3: Necessidade | I3: Data | J3: Data | K3: Embarques | L3: Meta | M3: Dias | N3: Necessidade | P3: Data | Q3: Data | R3: Embarques | S3: Meta | T3: Dias | U3: Necessidade | W3: Data | X3: Data | Y3: Embarques | Z3: Meta | AA3: Dias | AB3: Necessidade | AD3: Disciplina | AE3: Matrícula | AF3: Chave | AG3: Função | AH3: Projeto | AI3: Nome | AJ3: Embarques | AK3: Dias Emb. | AL3: Embarques | AM3: Dias Emb.
B4: 45505 | C4: =B4-1 -> 45504 | D4: =K4+R4+Y4 -> 1 | E4: =COUNTIFS(Equipe!F:F,"Novo",Equipe!D:D,"Técnico")*3 -> 90 | F4: =M4+T4+AA4 -> 12 | G4: =E4*14 -> 1260 | I4: 45505 | J4: =I4-1 -> 45504 | K4: =COUNTIFS('Planejamento IED'!C:C,"<"&J4,'Planejamento IED'!F:F,"Embarque",'Planejamento IED'!H:H,'Embarques Vivenciais'!$I$2,'Planejamento IED'!I:I,"Novo") -> 0 | L4: =COUNTIFS(Equipe!F:F,"Novo",Equipe!D:D,"Técnico",Equipe!E:E,$I$2)*3 -> 24 | M4: =SUMIFS('Planejamento IED'!E:E,'Planejamento IED'!C:C,"<"&J4,'Planejamento IED'!F:F,"Embarque",'Planejamento IED'!H:H,'Embarques Vivenciais'!$I$2,'Planejamento IED'!I:I,"Novo") -> 0 | N4: =L4*14 -> 336 | P4: 45505 | Q4: =P4-1 -> 45504 | R4: =COUNTIFS('Planejamento IED'!C:C,"<"&Q4,'Planejamento IED'!F:F,"Embarque",'Planejamento IED'!H:H,'Embarques Vivenciais'!$P$2,'Planejamento IED'!I:I,"Novo") -> 1 | S4: =COUNTIFS(Equipe!F:F,"Novo",Equipe!D:D,"Técnico",Equipe!E:E,$P$2)*3 -> 24 | T4: =SUMIFS('Planejamento IED'!E:E,'Planejamento IED'!C:C,"<"&Q4,'Planejamento IED'!F:F,"Embarque",'Planejamento IED'!H:H,'Embarques Vivenciais'!$P$2,'Planejamento IED'!I:I,"Novo") -> 12 | U4: =S4*14 -> 336 | W4: 45505 | X4: =W4-1 -> 45504 | Y4: =COUNTIFS('Planejamento IED'!C:C,"<"&X4,'Planejamento IED'!F:F,"Embarque",'Planejamento IED'!H:H,'Embarques Vivenciais'!$W$2,'Planejamento IED'!I:I,"Novo") -> 0 | Z4: =COUNTIFS(Equipe!F:F,"Novo",Equipe!D:D,"Técnico",Equipe!E:E,$W$2)*3 -> 21 | AA4: =SUMIFS('Planejamento IED'!E:E,'Planejamento IED'!C:C,"<"&X4,'Planejamento IED'!F:F,"Embarque",'Planejamento IED'!H:H,'Embarques Vivenciais'!$W$2,'Planejamento IED'!I:I,"Novo") -> 0 | AB4: =Z4*14 -> 294 | AD4: ELET | AE4: 4612171 | AF4: FWB5 | AG4: Técnico | AH4: P80 | AI4: TONICLER KUTZ | AJ4: =COUNTIFS('Planejamento IED'!A:A,'Embarques Vivenciais'!AI4,'Planejamento IED'!F:F,"Embarque",'Planejamento IED'!C:C,"<="&TODAY()) -> 3 | AK4: =SUMIFS('Planejamento IED'!E:E,'Planejamento IED'!A:A,AI4,'Planejamento IED'!F:F,"Embarque",'Planejamento IED'!D:D,"<="&TODAY()) -> 20 | AL4: =COUNTIFS('Planejamento IED'!A:A,'Embarques Vivenciais'!AI4,'Planejamento IED'!F:F,"Embarque") -> 4 | AM4: =SUMIFS('Planejamento IED'!E:E,'Planejamento IED'!A:A,AI4,'Planejamento IED'!F:F,"Embarque") -> 34
B5: 45536 | C5: =B5-1 -> 45535 | D5: =K5+R5+Y5 -> 1 | E5: =COUNTIFS(Equipe!F:F,"Novo",Equipe!D:D,"Técnico")*3 -> 90 | F5: =M5+T5+AA5 -> 12 | G5: =E5*14 -> 1260 | I5: 45536 | J5: =I5-1 -> 45535 | K5: =COUNTIFS('Planejamento IED'!C:C,"<"&J5,'Planejamento IED'!F:F,"Embarque",'Planejamento IED'!H:H,'Embarques Vivenciais'!$I$2,'Planejamento IED'!I:I,"Novo") -> 0 | L5: =COUNTIFS(Equipe!F:F,"Novo",Equipe!D:D,"Técnico",Equipe!E:E,$I$2)*3 -> 24 | M5: =SUMIFS('Planejamento IED'!E:E,'Planejamento IED'!C:C,"<"&J5,'Planejamento IED'!F:F,"Embarque",'Planejamento IED'!H:H,'Embarques Vivenciais'!$I$2,'Planejamento IED'!I:I,"Novo") -> 0 | N5: =L5*14 -> 336 | P5: 45536 | Q5: =P5-1 -> 45535 | R5: =COUNTIFS('Planejamento IED'!C:C,"<"&Q5,'Planejamento IED'!F:F,"Embarque",'Planejamento IED'!H:H,'Embarques Vivenciais'!$P$2,'Planejamento IED'!I:I,"Novo") -> 1 | S5: =COUNTIFS(Equipe!F:F,"Novo",Equipe!D:D,"Técnico",Equipe!E:E,$P$2)*3 -> 24 | T5: =SUMIFS('Planejamento IED'!E:E,'Planejamento IED'!C:C,"<"&Q5,'Planejamento IED'!F:F,"Embarque",'Planejamento IED'!H:H,'Embarques Vivenciais'!$P$2,'Planejamento IED'!I:I,"Novo") -> 12 | U5: =S5*14 -> 336 | W5: 45536 | X5: =W5-1 -> 45535 | Y5: =COUNTIFS('Planejamento IED'!C:C,"<"&X5,'Planejamento IED'!F:F,"Embarque",'Planejamento IED'!H:H,'Embarques Vivenciais'!$W$2,'Planejamento IED'!I:I,"Novo") -> 0 | Z5: =COUNTIFS(Equipe!F:F,"Novo",Equipe!D:D,"Técnico",Equipe!E:E,$W$2)*3 -> 21 | AA5: =SUMIFS('Planejamento IED'!E:E,'Planejamento IED'!C:C,"<"&X5,'Planejamento IED'!F:F,"Embarque",'Planejamento IED'!H:H,'Embarques Vivenciais'!$W$2,'Planejamento IED'!I:I,"Novo") -> 0 | AB5: =Z5*14 -> 294 | AD5: ELET | AE5: 4612050 | AF5: FW66 | AG5: Técnico | AH5: P82 | AI5: LUIZ FERNANDO | AJ5: =COUNTIFS('Planejamento IED'!A:A,'Embarques Vivenciais'!AI5,'Planejamento IED'!F:F,"Embarque",'Planejamento IED'!C:C,"<="&TODAY()) -> 2 | AK5: =SUMIFS('Planejamento IED'!E:E,'Planejamento IED'!A:A,AI5,'Planejamento IED'!F:F,"Embarque",'Planejamento IED'!D:D,"<="&TODAY()) -> 16 | AL5: =COUNTIFS('Planejamento IED'!A:A,'Embarques Vivenciais'!AI5,'Planejamento IED'!F:F,"Embarque") -> 2 | AM5: =SUMIFS('Planejamento IED'!E:E,'Planejamento IED'!A:A,AI5,'Planejamento IED'!F:F,"Embarque") -> 16
B6: 45566 | C6: =B6-1 -> 45565 | D6: =K6+R6+Y6 -> 2 | E6: =COUNTIFS(Equipe!F:F,"Novo",Equipe!D:D,"Técnico")*3 -> 90 | F6: =M6+T6+AA6 -> 24 | G6: =E6*14 -> 1260 | I6: 45566 | J6: =I6-1 -> 45565 | K6: =COUNTIFS('Planejamento IED'!C:C,"<"&J6,'Planejamento IED'!F:F,"Embarque",'Planejamento IED'!H:H,'Embarques Vivenciais'!$I$2,'Planejamento IED'!I:I,"Novo") -> 0 | L6: =COUNTIFS(Equipe!F:F,"Novo",Equipe!D:D,"Técnico",Equipe!E:E,$I$2)*3 -> 24 | M6: =SUMIFS('Planejamento IED'!E:E,'Planejamento IED'!C:C,"<"&J6,'Planejamento IED'!F:F,"Embarque",'Planejamento IED'!H:H,'Embarques Vivenciais'!$I$2,'Planejamento IED'!I:I,"Novo") -> 0 | N6: =L6*14 -> 336 | P6: 45566 | Q6: =P6-1 -> 45565 | R6: =COUNTIFS('Planejamento IED'!C:C,"<"&Q6,'Planejamento IED'!F:F,"Embarque",'Planejamento IED'!H:H,'Embarques Vivenciais'!$P$2,'Planejamento IED'!I:I,"Novo") -> 1 | S6: =COUNTIFS(Equipe!F:F,"Novo",Equipe!D:D,"Técnico",Equipe!E:E,$P$2)*3 -> 24 | T6: =SUMIFS('Planejamento IED'!E:E,'Planejamento IED'!C:C,"<"&Q6,'Planejamento IED'!F:F,"Embarque",'Planejamento IED'!H:H,'Embarques Vivenciais'!$P$2,'Planejamento IED'!I:I,"Novo") -> 12 | U6: =S6*14 -> 336 | W6: 45566 | X6: =W6-1 -> 45565 | Y6: =COUNTIFS('Planejamento IED'!C:C,"<"&X6,'Planejamento IED'!F:F,"Embarque",'Planejamento IED'!H:H,'Embarques Vivenciais'!$W$2,'Planejamento IED'!I:I,"Novo") -> 1 | Z6: =COUNTIFS(Equipe!F:F,"Novo",Equipe!D:D,"Técnico",Equipe!E:E,$W$2)*3 -> 21 | AA6: =SUMIFS('Planejamento IED'!E:E,'Planejamento IED'!C:C,"<"&X6,'Planejamento IED'!F:F,"Embarque",'Planejamento IED'!H:H,'Embarques Vivenciais'!$W$2,'Planejamento IED'!I:I,"Novo") -> 12 | AB6: =Z6*14 -> 294 | AD6: ELET | AE6: 4612140 | AF6: FVVS | AG6: Técnico | AH6: P83 | AI6: BRENO CARVALHO | AJ6: =COUNTIFS('Planejamento IED'!A:A,'Embarques Vivenciais'!AI6,'Planejamento IED'!F:F,"Embarque",'Planejamento IED'!C:C,"<="&TODAY()) -> 4 | AK6: =SUMIFS('Planejamento IED'!E:E,'Planejamento IED'!A:A,AI6,'Planejamento IED'!F:F,"Embarque",'Planejamento IED'!D:D,"<="&TODAY()) -> 42 | AL6: =COUNTIFS('Planejamento IED'!A:A,'Embarques Vivenciais'!AI6,'Planejamento IED'!F:F,"Embarque") -> 4 | AM6: =SUMIFS('Planejamento IED'!E:E,'Planejamento IED'!A:A,AI6,'Planejamento IED'!F:F,"Embarque") -> 42
B7: 45597 | C7: =B7-1 -> 45596 | D7: =K7+R7+Y7 -> 2 | E7: =COUNTIFS(Equipe!F:F,"Novo",Equipe!D:D,"Técnico")*3 -> 90 | F7: =M7+T7+AA7 -> 24 | G7: =E7*14 -> 1260 | I7: 45597 | J7: =I7-1 -> 45596 | K7: =COUNTIFS('Planejamento IED'!C:C,"<"&J7,'Planejamento IED'!F:F,"Embarque",'Planejamento IED'!H:H,'Embarques Vivenciais'!$I$2,'Planejamento IED'!I:I,"Novo") -> 0 | L7: =COUNTIFS(Equipe!F:F,"Novo",Equipe!D:D,"Técnico",Equipe!E:E,$I$2)*3 -> 24 | M7: =SUMIFS('Planejamento IED'!E:E,'Planejamento IED'!C:C,"<"&J7,'Planejamento IED'!F:F,"Embarque",'Planejamento IED'!H:H,'Embarques Vivenciais'!$I$2,'Planejamento IED'!I:I,"Novo") -> 0 | N7: =L7*14 -> 336 | P7: 45597 | Q7: =P7-1 -> 45596 | R7: =COUNTIFS('Planejamento IED'!C:C,"<"&Q7,'Planejamento IED'!F:F,"Embarque",'Planejamento IED'!H:H,'Embarques Vivenciais'!$P$2,'Planejamento IED'!I:I,"Novo") -> 1 | S7: =COUNTIFS(Equipe!F:F,"Novo",Equipe!D:D,"Técnico",Equipe!E:E,$P$2)*3 -> 24 | T7: =SUMIFS('Planejamento IED'!E:E,'Planejamento IED'!C:C,"<"&Q7,'Planejamento IED'!F:F,"Embarque",'Planejamento IED'!H:H,'Embarques Vivenciais'!$P$2,'Planejamento IED'!I:I,"Novo") -> 12 | U7: =S7*14 -> 336 | W7: 45597 | X7: =W7-1 -> 45596 | Y7: =COUNTIFS('Planejamento IED'!C:C,"<"&X7,'Planejamento IED'!F:F,"Embarque",'Planejamento IED'!H:H,'Embarques Vivenciais'!$W$2,'Planejamento IED'!I:I,"Novo") -> 1 | Z7: =COUNTIFS(Equipe!F:F,"Novo",Equipe!D:D,"Técnico",Equipe!E:E,$W$2)*3 -> 21 | AA7: =SUMIFS('Planejamento IED'!E:E,'Planejamento IED'!C:C,"<"&X7,'Planejamento IED'!F:F,"Embarque",'Planejamento IED'!H:H,'Embarques Vivenciais'!$W$2,'Planejamento IED'!I:I,"Novo") -> 12 | AB7: =Z7*14 -> 294 | AD7: INST | AE7: 4612243 | AF7: FWCC | AG7: Técnico | AH7: P80 | AI7: PABLO ALMEIDA | AJ7: =COUNTIFS('Planejamento IED'!A:A,'Embarques Vivenciais'!AI7,'Planejamento IED'!F:F,"Embarque",'Planejamento IED'!C:C,"<="&TODAY()) -> 2 | AK7: =SUMIFS('Planejamento IED'!E:E,'Planejamento IED'!A:A,AI7,'Planejamento IED'!F:F,"Embarque",'Planejamento IED'!D:D,"<="&TODAY()) -> 19 | AL7: =COUNTIFS('Planejamento IED'!A:A,'Embarques Vivenciais'!AI7,'Planejamento IED'!F:F,"Embarque") -> 2 | AM7: =SUMIFS('Planejamento IED'!E:E,'Planejamento IED'!A:A,AI7,'Planejamento IED'!F:F,"Embarque") -> 19
B8: 45627 | C8: =B8-1 -> 45626 | D8: =K8+R8+Y8 -> 2 | E8: =COUNTIFS(Equipe!F:F,"Novo",Equipe!D:D,"Técnico")*3 -> 90 | F8: =M8+T8+AA8 -> 24 | G8: =E8*14 -> 1260 | I8: 45627 | J8: =I8-1 -> 45626 | K8: =COUNTIFS('Planejamento IED'!C:C,"<"&J8,'Planejamento IED'!F:F,"Embarque",'Planejamento IED'!H:H,'Embarques Vivenciais'!$I$2,'Planejamento IED'!I:I,"Novo") -> 0 | L8: =COUNTIFS(Equipe!F:F,"Novo",Equipe!D:D,"Técnico",Equipe!E:E,$I$2)*3 -> 24 | M8: =SUMIFS('Planejamento IED'!E:E,'Planejamento IED'!C:C,"<"&J8,'Planejamento IED'!F:F,"Embarque",'Planejamento IED'!H:H,'Embarques Vivenciais'!$I$2,'Planejamento IED'!I:I,"Novo") -> 0 | N8: =L8*14 -> 336 | P8: 45627 | Q8: =P8-1 -> 45626 | R8: =COUNTIFS('Planejamento IED'!C:C,"<"&Q8,'Planejamento IED'!F:F,"Embarque",'Planejamento IED'!H:H,'Embarques Vivenciais'!$P$2,'Planejamento IED'!I:I,"Novo") -> 1 | S8: =COUNTIFS(Equipe!F:F,"Novo",Equipe!D:D,"Técnico",Equipe!E:E,$P$2)*3 -> 24 | T8: =SUMIFS('Planejamento IED'!E:E,'Planejamento IED'!C:C,"<"&Q8,'Planejamento IED'!F:F,"Embarque",'Planejamento IED'!H:H,'Embarques Vivenciais'!$P$2,'Planejamento IED'!I:I,"Novo") -> 12 | U8: =S8*14 -> 336 | W8: 45627 | X8: =W8-1 -> 45626 | Y8: =COUNTIFS('Planejamento IED'!C:C,"<"&X8,'Planejamento IED'!F:F,"Embarque",'Planejamento IED'!H:H,'Embarques Vivenciais'!$W$2,'Planejamento IED'!I:I,"Novo") -> 1 | Z8: =COUNTIFS(Equipe!F:F,"Novo",Equipe!D:D,"Técnico",Equipe!E:E,$W$2)*3 -> 21 | AA8: =SUMIFS('Planejamento IED'!E:E,'Planejamento IED'!C:C,"<"&X8,'Planejamento IED'!F:F,"Embarque",'Planejamento IED'!H:H,'Embarques Vivenciais'!$W$2,'Planejamento IED'!I:I,"Novo") -> 12 | AB8: =Z8*14 -> 294 | AD8: INST | AE8: 4612389 | AF8: FVX0 | AG8: Técnico | AH8: P80 | AI8: RONALD QUARESMA | AJ8: =COUNTIFS('Planejamento IED'!A:A,'Embarques Vivenciais'!AI8,'Planejamento IED'!F:F,"Embarque",'Planejamento IED'!C:C,"<="&TODAY()) -> 0 | AK8: =SUMIFS('Planejamento IED'!E:E,'Planejamento IED'!A:A,AI8,'Planejamento IED'!F:F,"Embarque",'Planejamento IED'!D:D,"<="&TODAY()) -> 0 | AL8: =COUNTIFS('Planejamento IED'!A:A,'Embarques Vivenciais'!AI8,'Planejamento IED'!F:F,"Embarque") -> 0 | AM8: =SUMIFS('Planejamento IED'!E:E,'Planejamento IED'!A:A,AI8,'Planejamento IED'!F:F,"Embarque") -> 0
B9: 45658 | C9: =B9-1 -> 45657 | D9: =K9+R9+Y9 -> 2 | E9: =COUNTIFS(Equipe!F:F,"Novo",Equipe!D:D,"Técnico")*3 -> 90 | F9: =M9+T9+AA9 -> 24 | G9: =E9*14 -> 1260 | I9: 45658 | J9: =I9-1 -> 45657 | K9: =COUNTIFS('Planejamento IED'!C:C,"<"&J9,'Planejamento IED'!F:F,"Embarque",'Planejamento IED'!H:H,'Embarques Vivenciais'!$I$2,'Planejamento IED'!I:I,"Novo") -> 0 | L9: =COUNTIFS(Equipe!F:F,"Novo",Equipe!D:D,"Técnico",Equipe!E:E,$I$2)*3 -> 24 | M9: =SUMIFS('Planejamento IED'!E:E,'Planejamento IED'!C:C,"<"&J9,'Planejamento IED'!F:F,"Embarque",'Planejamento IED'!H:H,'Embarques Vivenciais'!$I$2,'Planejamento IED'!I:I,"Novo") -> 0 | N9: =L9*14 -> 336 | P9: 45658 | Q9: =P9-1 -> 45657 | R9: =COUNTIFS('Planejamento IED'!C:C,"<"&Q9,'Planejamento IED'!F:F,"Embarque",'Planejamento IED'!H:H,'Embarques Vivenciais'!$P$2,'Planejamento IED'!I:I,"Novo") -> 1 | S9: =COUNTIFS(Equipe!F:F,"Novo",Equipe!D:D,"Técnico",Equipe!E:E,$P$2)*3 -> 24 | T9: =SUMIFS('Planejamento IED'!E:E,'Planejamento IED'!C:C,"<"&Q9,'Planejamento IED'!F:F,"Embarque",'Planejamento IED'!H:H,'Embarques Vivenciais'!$P$2,'Planejamento IED'!I:I,"Novo") -> 12 | U9: =S9*14 -> 336 | W9: 45658 | X9: =W9-1 -> 45657 | Y9: =COUNTIFS('Planejamento IED'!C:C,"<"&X9,'Planejamento IED'!F:F,"Embarque",'Planejamento IED'!H:H,'Embarques Vivenciais'!$W$2,'Planejamento IED'!I:I,"Novo") -> 1 | Z9: =COUNTIFS(Equipe!F:F,"Novo",Equipe!D:D,"Técnico",Equipe!E:E,$W$2)*3 -> 21 | AA9: =SUMIFS('Planejamento IED'!E:E,'Planejamento IED'!C:C,"<"&X9,'Planejamento IED'!F:F,"Embarque",'Planejamento IED'!H:H,'Embarques Vivenciais'!$W$2,'Planejamento IED'!I:I,"Novo") -> 12 | AB9: =Z9*14 -> 294 | AD9: INST | AE9: 4612192 | AF9: FVV0 | AG9: Técnico | AH9: P82 | AI9: VICTOR CAMPOS | AJ9: =COUNTIFS('Planejamento IED'!A:A,'Embarques Vivenciais'!AI9,'Planejamento IED'!F:F,"Embarque",'Planejamento IED'!C:C,"<="&TODAY()) -> 2 | AK9: =SUMIFS('Planejamento IED'!E:E,'Planejamento IED'!A:A,AI9,'Planejamento IED'!F:F,"Embarque",'Planejamento IED'!D:D,"<="&TODAY()) -> 28 | AL9: =COUNTIFS('Planejamento IED'!A:A,'Embarques Vivenciais'!AI9,'Planejamento IED'!F:F,"Embarque") -> 2 | AM9: =SUMIFS('Planejamento IED'!E:E,'Planejamento IED'!A:A,AI9,'Planejamento IED'!F:F,"Embarque") -> 28
B10: 45689 | C10: =B10-1 -> 45688 | D10: =K10+R10+Y10 -> 3 | E10: =COUNTIFS(Equipe!F:F,"Novo",Equipe!D:D,"Técnico")*3 -> 90 | F10: =M10+T10+AA10 -> 31 | G10: =E10*14 -> 1260 | I10: 45689 | J10: =I10-1 -> 45688 | K10: =COUNTIFS('Planejamento IED'!C:C,"<"&J10,'Planejamento IED'!F:F,"Embarque",'Planejamento IED'!H:H,'Embarques Vivenciais'!$I$2,'Planejamento IED'!I:I,"Novo") -> 1 | L10: =COUNTIFS(Equipe!F:F,"Novo",Equipe!D:D,"Técnico",Equipe!E:E,$I$2)*3 -> 24 | M10: =SUMIFS('Planejamento IED'!E:E,'Planejamento IED'!C:C,"<"&J10,'Planejamento IED'!F:F,"Embarque",'Planejamento IED'!H:H,'Embarques Vivenciais'!$I$2,'Planejamento IED'!I:I,"Novo") -> 7 | N10: =L10*14 -> 336 | P10: 45689 | Q10: =P10-1 -> 45688 | R10: =COUNTIFS('Planejamento IED'!C:C,"<"&Q10,'Planejamento IED'!F:F,"Embarque",'Planejamento IED'!H:H,'Embarques Vivenciais'!$P$2,'Planejamento IED'!I:I,"Novo") -> 1 | S10: =COUNTIFS(Equipe!F:F,"Novo",Equipe!D:D,"Técnico",Equipe!E:E,$P$2)*3 -> 24 | T10: =SUMIFS('Planejamento IED'!E:E,'Planejamento IED'!C:C,"<"&Q10,'Planejamento IED'!F:F,"Embarque",'Planejamento IED'!H:H,'Embarques Vivenciais'!$P$2,'Planejamento IED'!I:I,"Novo") -> 12 | U10: =S10*14 -> 336 | W10: 45689 | X10: =W10-1 -> 45688 | Y10: =COUNTIFS('Planejamento IED'!C:C,"<"&X10,'Planejamento IED'!F:F,"Embarque",'Planejamento IED'!H:H,'Embarques Vivenciais'!$W$2,'Planejamento IED'!I:I,"Novo") -> 1 | Z10: =COUNTIFS(Equipe!F:F,"Novo",Equipe!D:D,"Técnico",Equipe!E:E,$W$2)*3 -> 21 | AA10: =SUMIFS('Planejamento IED'!E:E,'Planejamento IED'!C:C,"<"&X10,'Planejamento IED'!F:F,"Embarque",'Planejamento IED'!H:H,'Embarques Vivenciais'!$W$2,'Planejamento IED'!I:I,"Novo") -> 12 | AB10: =Z10*14 -> 294 | AD10: INST | AE10: 4612393 | AF10: FVWH | AG10: Técnico | AH10: P83 | AI10: JAILTON CONCEIÇÃO | AJ10: =COUNTIFS('Planejamento IED'!A:A,'Embarques Vivenciais'!AI10,'Planejamento IED'!F:F,"Embarque",'Planejamento IED'!C:C,"<="&TODAY()) -> 4 | AK10: =SUMIFS('Planejamento IED'!E:E,'Planejamento IED'!A:A,AI10,'Planejamento IED'!F:F,"Embarque",'Planejamento IED'!D:D,"<="&TODAY()) -> 41 | AL10: =COUNTIFS('Planejamento IED'!A:A,'Embarques Vivenciais'!AI10,'Planejamento IED'!F:F,"Embarque") -> 4 | AM10: =SUMIFS('Planejamento IED'!E:E,'Planejamento IED'!A:A,AI10,'Planejamento IED'!F:F,"Embarque") -> 41
B11: 45717 | C11: =B11-1 -> 45716 | D11: =K11+R11+Y11 -> 3 | E11: =COUNTIFS(Equipe!F:F,"Novo",Equipe!D:D,"Técnico")*3 -> 90 | F11: =M11+T11+AA11 -> 31 | G11: =E11*14 -> 1260 | I11: 45717 | J11: =I11-1 -> 45716 | K11: =COUNTIFS('Planejamento IED'!C:C,"<"&J11,'Planejamento IED'!F:F,"Embarque",'Planejamento IED'!H:H,'Embarques Vivenciais'!$I$2,'Planejamento IED'!I:I,"Novo") -> 1 | L11: =COUNTIFS(Equipe!F:F,"Novo",Equipe!D:D,"Técnico",Equipe!E:E,$I$2)*3 -> 24 | M11: =SUMIFS('Planejamento IED'!E:E,'Planejamento IED'!C:C,"<"&J11,'Planejamento IED'!F:F,"Embarque",'Planejamento IED'!H:H,'Embarques Vivenciais'!$I$2,'Planejamento IED'!I:I,"Novo") -> 7 | N11: =L11*14 -> 336 | P11: 45717 | Q11: =P11-1 -> 45716 | R11: =COUNTIFS('Planejamento IED'!C:C,"<"&Q11,'Planejamento IED'!F:F,"Embarque",'Planejamento IED'!H:H,'Embarques Vivenciais'!$P$2,'Planejamento IED'!I:I,"Novo") -> 1 | S11: =COUNTIFS(Equipe!F:F,"Novo",Equipe!D:D,"Técnico",Equipe!E:E,$P$2)*3 -> 24 | T11: =SUMIFS('Planejamento IED'!E:E,'Planejamento IED'!C:C,"<"&Q11,'Planejamento IED'!F:F,"Embarque",'Planejamento IED'!H:H,'Embarques Vivenciais'!$P$2,'Planejamento IED'!I:I,"Novo") -> 12 | U11: =S11*14 -> 336 | W11: 45717 | X11: =W11-1 -> 45716 | Y11: =COUNTIFS('Planejamento IED'!C:C,"<"&X11,'Planejamento IED'!F:F,"Embarque",'Planejamento IED'!H:H,'Embarques Vivenciais'!$W$2,'Planejamento IED'!I:I,"Novo") -> 1 | Z11: =COUNTIFS(Equipe!F:F,"Novo",Equipe!D:D,"Técnico",Equipe!E:E,$W$2)*3 -> 21 | AA11: =SUMIFS('Planejamento IED'!E:E,'Planejamento IED'!C:C,"<"&X11,'Planejamento IED'!F:F,"Embarque",'Planejamento IED'!H:H,'Embarques Vivenciais'!$W$2,'Planejamento IED'!I:I,"Novo") -> 12 | AB11: =Z11*14 -> 294 | AD11: INST | AE11: 4612228 | AF11: FWNL | AG11: Técnico | AH11: P82 | AI11: LUIZ SERPA | AJ11: =COUNTIFS('Planejamento IED'!A:A,'Embarques Vivenciais'!AI11,'Planejamento IED'!F:F,"Embarque",'Planejamento IED'!C:C,"<="&TODAY()) -> 2 | AK11: =SUMIFS('Planejamento IED'!E:E,'Planejamento IED'!A:A,AI11,'Planejamento IED'!F:F,"Embarque",'Planejamento IED'!D:D,"<="&TODAY()) -> 19 | AL11: =COUNTIFS('Planejamento IED'!A:A,'Embarques Vivenciais'!AI11,'Planejamento IED'!F:F,"Embarque") -> 2 | AM11: =SUMIFS('Planejamento IED'!E:E,'Planejamento IED'!A:A,AI11,'Planejamento IED'!F:F,"Embarque") -> 19
B12: 45748 | C12: =B12-1 -> 45747 | D12: =K12+R12+Y12 -> 4 | E12: =COUNTIFS(Equipe!F:F,"Novo",Equipe!D:D,"Técnico")*3 -> 90 | F12: =M12+T12+AA12 -> 45 | G12: =E12*14 -> 1260 | I12: 45748 | J12: =I12-1 -> 45747 | K12: =COUNTIFS('Planejamento IED'!C:C,"<"&J12,'Planejamento IED'!F:F,"Embarque",'Planejamento IED'!H:H,'Embarques Vivenciais'!$I$2,'Planejamento IED'!I:I,"Novo") -> 2 | L12: =COUNTIFS(Equipe!F:F,"Novo",Equipe!D:D,"Técnico",Equipe!E:E,$I$2)*3 -> 24 | M12: =SUMIFS('Planejamento IED'!E:E,'Planejamento IED'!C:C,"<"&J12,'Planejamento IED'!F:F,"Embarque",'Planejamento IED'!H:H,'Embarques Vivenciais'!$I$2,'Planejamento IED'!I:I,"Novo") -> 21 | N12: =L12*14 -> 336 | P12: 45748 | Q12: =P12-1 -> 45747 | R12: =COUNTIFS('Planejamento IED'!C:C,"<"&Q12,'Planejamento IED'!F:F,"Embarque",'Planejamento IED'!H:H,'Embarques Vivenciais'!$P$2,'Planejamento IED'!I:I,"Novo") -> 1 | S12: =COUNTIFS(Equipe!F:F,"Novo",Equipe!D:D,"Técnico",Equipe!E:E,$P$2)*3 -> 24 | T12: =SUMIFS('Planejamento IED'!E:E,'Planejamento IED'!C:C,"<"&Q12,'Planejamento IED'!F:F,"Embarque",'Planejamento IED'!H:H,'Embarques Vivenciais'!$P$2,'Planejamento IED'!I:I,"Novo") -> 12 | U12: =S12*14 -> 336 | W12: 45748 | X12: =W12-1 -> 45747 | Y12: =COUNTIFS('Planejamento IED'!C:C,"<"&X12,'Planejamento IED'!F:F,"Embarque",'Planejamento IED'!H:H,'Embarques Vivenciais'!$W$2,'Planejamento IED'!I:I,"Novo") -> 1 | Z12: =COUNTIFS(Equipe!F:F,"Novo",Equipe!D:D,"Técnico",Equipe!E:E,$W$2)*3 -> 21 | AA12: =SUMIFS('Planejamento IED'!E:E,'Planejamento IED'!C:C,"<"&X12,'Planejamento IED'!F:F,"Embarque",'Planejamento IED'!H:H,'Embarques Vivenciais'!$W$2,'Planejamento IED'!I:I,"Novo") -> 12 | AB12: =Z12*14 -> 294 | AD12: INST | AE12: 4612247 | AF12: FW96 | AG12: Técnico | AH12: P83 | AI12: RICARDO UEMA | AJ12: =COUNTIFS('Planejamento IED'!A:A,'Embarques Vivenciais'!AI12,'Planejamento IED'!F:F,"Embarque",'Planejamento IED'!C:C,"<="&TODAY()) -> 2 | AK12: =SUMIFS('Planejamento IED'!E:E,'Planejamento IED'!A:A,AI12,'Planejamento IED'!F:F,"Embarque",'Planejamento IED'!D:D,"<="&TODAY()) -> 25 | AL12: =COUNTIFS('Planejamento IED'!A:A,'Embarques Vivenciais'!AI12,'Planejamento IED'!F:F,"Embarque") -> 2 | AM12: =SUMIFS('Planejamento IED'!E:E,'Planejamento IED'!A:A,AI12,'Planejamento IED'!F:F,"Embarque") -> 25
B13: 45778 | C13: =B13-1 -> 45777 | D13: =K13+R13+Y13 -> 6 | E13: =COUNTIFS(Equipe!F:F,"Novo",Equipe!D:D,"Técnico")*3 -> 90 | F13: =M13+T13+AA13 -> 51 | G13: =E13*14 -> 1260 | I13: 45778 | J13: =I13-1 -> 45777 | K13: =COUNTIFS('Planejamento IED'!C:C,"<"&J13,'Planejamento IED'!F:F,"Embarque",'Planejamento IED'!H:H,'Embarques Vivenciais'!$I$2,'Planejamento IED'!I:I,"Novo") -> 3 | L13: =COUNTIFS(Equipe!F:F,"Novo",Equipe!D:D,"Técnico",Equipe!E:E,$I$2)*3 -> 24 | M13: =SUMIFS('Planejamento IED'!E:E,'Planejamento IED'!C:C,"<"&J13,'Planejamento IED'!F:F,"Embarque",'Planejamento IED'!H:H,'Embarques Vivenciais'!$I$2,'Planejamento IED'!I:I,"Novo") -> 24 | N13: =L13*14 -> 336 | P13: 45778 | Q13: =P13-1 -> 45777 | R13: =COUNTIFS('Planejamento IED'!C:C,"<"&Q13,'Planejamento IED'!F:F,"Embarque",'Planejamento IED'!H:H,'Embarques Vivenciais'!$P$2,'Planejamento IED'!I:I,"Novo") -> 1 | S13: =COUNTIFS(Equipe!F:F,"Novo",Equipe!D:D,"Técnico",Equipe!E:E,$P$2)*3 -> 24 | T13: =SUMIFS('Planejamento IED'!E:E,'Planejamento IED'!C:C,"<"&Q13,'Planejamento IED'!F:F,"Embarque",'Planejamento IED'!H:H,'Embarques Vivenciais'!$P$2,'Planejamento IED'!I:I,"Novo") -> 12 | U13: =S13*14 -> 336 | W13: 45778 | X13: =W13-1 -> 45777 | Y13: =COUNTIFS('Planejamento IED'!C:C,"<"&X13,'Planejamento IED'!F:F,"Embarque",'Planejamento IED'!H:H,'Embarques Vivenciais'!$W$2,'Planejamento IED'!I:I,"Novo") -> 2 | Z13: =COUNTIFS(Equipe!F:F,"Novo",Equipe!D:D,"Técnico",Equipe!E:E,$W$2)*3 -> 21 | AA13: =SUMIFS('Planejamento IED'!E:E,'Planejamento IED'!C:C,"<"&X13,'Planejamento IED'!F:F,"Embarque",'Planejamento IED'!H:H,'Embarques Vivenciais'!$W$2,'Planejamento IED'!I:I,"Novo") -> 15 | AB13: =Z13*14 -> 294 | AD13: MEC | AE13: 4612098 | AF13: FW44 | AG13: Técnico | AH13: P80 | AI13: ANDRE SILVA | AJ13: =COUNTIFS('Planejamento IED'!A:A,'Embarques Vivenciais'!AI13,'Planejamento IED'!F:F,"Embarque",'Planejamento IED'!C:C,"<="&TODAY()) -> 4 | AK13: =SUMIFS('Planejamento IED'!E:E,'Planejamento IED'!A:A,AI13,'Planejamento IED'!F:F,"Embarque",'Planejamento IED'!D:D,"<="&TODAY()) -> 52 | AL13: =COUNTIFS('Planejamento IED'!A:A,'Embarques Vivenciais'!AI13,'Planejamento IED'!F:F,"Embarque") -> 4 | AM13: =SUMIFS('Planejamento IED'!E:E,'Planejamento IED'!A:A,AI13,'Planejamento IED'!F:F,"Embarque") -> 52
B14: 45809 | C14: =B14-1 -> 45808 | D14: =K14+R14+Y14 -> 10 | E14: =COUNTIFS(Equipe!F:F,"Novo",Equipe!D:D,"Técnico")*3 -> 90 | F14: =M14+T14+AA14 -> 89 | G14: =E14*14 -> 1260 | I14: 45809 | J14: =I14-1 -> 45808 | K14: =COUNTIFS('Planejamento IED'!C:C,"<"&J14,'Planejamento IED'!F:F,"Embarque",'Planejamento IED'!H:H,'Embarques Vivenciais'!$I$2,'Planejamento IED'!I:I,"Novo") -> 5 | L14: =COUNTIFS(Equipe!F:F,"Novo",Equipe!D:D,"Técnico",Equipe!E:E,$I$2)*3 -> 24 | M14: =SUMIFS('Planejamento IED'!E:E,'Planejamento IED'!C:C,"<"&J14,'Planejamento IED'!F:F,"Embarque",'Planejamento IED'!H:H,'Embarques Vivenciais'!$I$2,'Planejamento IED'!I:I,"Novo") -> 44 | N14: =L14*14 -> 336 | P14: 45809 | Q14: =P14-1 -> 45808 | R14: =COUNTIFS('Planejamento IED'!C:C,"<"&Q14,'Planejamento IED'!F:F,"Embarque",'Planejamento IED'!H:H,'Embarques Vivenciais'!$P$2,'Planejamento IED'!I:I,"Novo") -> 2 | S14: =COUNTIFS(Equipe!F:F,"Novo",Equipe!D:D,"Técnico",Equipe!E:E,$P$2)*3 -> 24 | T14: =SUMIFS('Planejamento IED'!E:E,'Planejamento IED'!C:C,"<"&Q14,'Planejamento IED'!F:F,"Embarque",'Planejamento IED'!H:H,'Embarques Vivenciais'!$P$2,'Planejamento IED'!I:I,"Novo") -> 17 | U14: =S14*14 -> 336 | W14: 45809 | X14: =W14-1 -> 45808 | Y14: =COUNTIFS('Planejamento IED'!C:C,"<"&X14,'Planejamento IED'!F:F,"Embarque",'Planejamento IED'!H:H,'Embarques Vivenciais'!$W$2,'Planejamento IED'!I:I,"Novo") -> 3 | Z14: =COUNTIFS(Equipe!F:F,"Novo",Equipe!D:D,"Técnico",Equipe!E:E,$W$2)*3 -> 21 | AA14: =SUMIFS('Planejamento IED'!E:E,'Planejamento IED'!C:C,"<"&X14,'Planejamento IED'!F:F,"Embarque",'Planejamento IED'!H:H,'Embarques Vivenciais'!$W$2,'Planejamento IED'!I:I,"Novo") -> 28 | AB14: =Z14*14 -> 294 | AD14: MEC | AE14: 4612126 | AF14: FW52 | AG14: Técnico | AH14: P82 | AI14: THIELLES GUSTAVO | AJ14: =COUNTIFS('Planejamento IED'!A:A,'Embarques Vivenciais'!AI14,'Planejamento IED'!F:F,"Embarque",'Planejamento IED'!C:C,"<="&TODAY()) -> 5 | AK14: =SUMIFS('Planejamento IED'!E:E,'Planejamento IED'!A:A,AI14,'Planejamento IED'!F:F,"Embarque",'Planejamento IED'!D:D,"<="&TODAY()) -> 62 | AL14: =COUNTIFS('Planejamento IED'!A:A,'Embarques Vivenciais'!AI14,'Planejamento IED'!F:F,"Embarque") -> 5 | AM14: =SUMIFS('Planejamento IED'!E:E,'Planejamento IED'!A:A,AI14,'Planejamento IED'!F:F,"Embarque") -> 62
B15: 45839 | C15: =B15-1 -> 45838 | D15: =K15+R15+Y15 -> 13 | E15: =COUNTIFS(Equipe!F:F,"Novo",Equipe!D:D,"Técnico")*3 -> 90 | F15: =M15+T15+AA15 -> 114 | G15: =E15*14 -> 1260 | I15: 45839 | J15: =I15-1 -> 45838 | K15: =COUNTIFS('Planejamento IED'!C:C,"<"&J15,'Planejamento IED'!F:F,"Embarque",'Planejamento IED'!H:H,'Embarques Vivenciais'!$I$2,'Planejamento IED'!I:I,"Novo") -> 6 | L15: =COUNTIFS(Equipe!F:F,"Novo",Equipe!D:D,"Técnico",Equipe!E:E,$I$2)*3 -> 24 | M15: =SUMIFS('Planejamento IED'!E:E,'Planejamento IED'!C:C,"<"&J15,'Planejamento IED'!F:F,"Embarque",'Planejamento IED'!H:H,'Embarques Vivenciais'!$I$2,'Planejamento IED'!I:I,"Novo") -> 57 | N15: =L15*14 -> 336 | P15: 45839 | Q15: =P15-1 -> 45838 | R15: =COUNTIFS('Planejamento IED'!C:C,"<"&Q15,'Planejamento IED'!F:F,"Embarque",'Planejamento IED'!H:H,'Embarques Vivenciais'!$P$2,'Planejamento IED'!I:I,"Novo") -> 4 | S15: =COUNTIFS(Equipe!F:F,"Novo",Equipe!D:D,"Técnico",Equipe!E:E,$P$2)*3 -> 24 | T15: =SUMIFS('Planejamento IED'!E:E,'Planejamento IED'!C:C,"<"&Q15,'Planejamento IED'!F:F,"Embarque",'Planejamento IED'!H:H,'Embarques Vivenciais'!$P$2,'Planejamento IED'!I:I,"Novo") -> 29 | U15: =S15*14 -> 336 | W15: 45839 | X15: =W15-1 -> 45838 | Y15: =COUNTIFS('Planejamento IED'!C:C,"<"&X15,'Planejamento IED'!F:F,"Embarque",'Planejamento IED'!H:H,'Embarques Vivenciais'!$W$2,'Planejamento IED'!I:I,"Novo") -> 3 | Z15: =COUNTIFS(Equipe!F:F,"Novo",Equipe!D:D,"Técnico",Equipe!E:E,$W$2)*3 -> 21 | AA15: =SUMIFS('Planejamento IED'!E:E,'Planejamento IED'!C:C,"<"&X15,'Planejamento IED'!F:F,"Embarque",'Planejamento IED'!H:H,'Embarques Vivenciais'!$W$2,'Planejamento IED'!I:I,"Novo") -> 28 | AB15: =Z15*14 -> 294 | AD15: ELET | AE15: 9842940 | AF15: HFO8 | AG15: Técnico | AH15: P80 | AI15: JORGE HENRIQUE | AJ15: =COUNTIFS('Planejamento IED'!A:A,'Embarques Vivenciais'!AI15,'Planejamento IED'!F:F,"Embarque",'Planejamento IED'!C:C,"<="&TODAY()) -> 4 | AK15: =SUMIFS('Planejamento IED'!E:E,'Planejamento IED'!A:A,AI15,'Planejamento IED'!F:F,"Embarque",'Planejamento IED'!D:D,"<="&TODAY()) -> 45 | AL15: =COUNTIFS('Planejamento IED'!A:A,'Embarques Vivenciais'!AI15,'Planejamento IED'!F:F,"Embarque") -> 4 | AM15: =SUMIFS('Planejamento IED'!E:E,'Planejamento IED'!A:A,AI15,'Planejamento IED'!F:F,"Embarque") -> 45
... B26: 46174 | C26: =B26-1 -> 46173 | D26: =K26+R26+Y26 -> 57 | E26: =COUNTIFS(Equipe!F:F,"Novo",Equipe!D:D,"Técnico")*3 -> 90 | F26: =M26+T26+AA26 -> 586 | G26: =E26*14 -> 1260 | I26: 46174 | J26: =I26-1 -> 46173 | K26: =COUNTIFS('Planejamento IED'!C:C,"<"&J26,'Planejamento IED'!F:F,"Embarque",'Planejamento IED'!H:H,'Embarques Vivenciais'!$I$2,'Planejamento IED'!I:I,"Novo") -> 20 | L26: =COUNTIFS(Equipe!F:F,"Novo",Equipe!D:D,"Técnico",Equipe!E:E,$I$2)*3 -> 24 | M26: =SUMIFS('Planejamento IED'!E:E,'Planejamento IED'!C:C,"<"&J26,'Planejamento IED'!F:F,"Embarque",'Planejamento IED'!H:H,'Embarques Vivenciais'!$I$2,'Planejamento IED'!I:I,"Novo") -> 215 | N26: =L26*14 -> 336 | P26: 46174 | Q26: =P26-1 -> 46173 | R26: =COUNTIFS('Planejamento IED'!C:C,"<"&Q26,'Planejamento IED'!F:F,"Embarque",'Planejamento IED'!H:H,'Embarques Vivenciais'!$P$2,'Planejamento IED'!I:I,"Novo") -> 20 | S26: =COUNTIFS(Equipe!F:F,"Novo",Equipe!D:D,"Técnico",Equipe!E:E,$P$2)*3 -> 24 | T26: =SUMIFS('Planejamento IED'!E:E,'Planejamento IED'!C:C,"<"&Q26,'Planejamento IED'!F:F,"Embarque",'Planejamento IED'!H:H,'Embarques Vivenciais'!$P$2,'Planejamento IED'!I:I,"Novo") -> 221 | U26: =S26*14 -> 336 | W26: 46174 | X26: =W26-1 -> 46173 | Y26: =COUNTIFS('Planejamento IED'!C:C,"<"&X26,'Planejamento IED'!F:F,"Embarque",'Planejamento IED'!H:H,'Embarques Vivenciais'!$W$2,'Planejamento IED'!I:I,"Novo") -> 17 | Z26: =COUNTIFS(Equipe!F:F,"Novo",Equipe!D:D,"Técnico",Equipe!E:E,$W$2)*3 -> 21 | AA26: =SUMIFS('Planejamento IED'!E:E,'Planejamento IED'!C:C,"<"&X26,'Planejamento IED'!F:F,"Embarque",'Planejamento IED'!H:H,'Embarques Vivenciais'!$W$2,'Planejamento IED'!I:I,"Novo") -> 150 | AB26: =Z26*14 -> 294 | AD26: MEC | AE26: 4613186 | AF26: G7PT | AG26: Técnico | AH26: P83 | AI26: EDISON NOVAES | AJ26: =COUNTIFS('Planejamento IED'!A:A,'Embarques Vivenciais'!AI26,'Planejamento IED'!F:F,"Embarque",'Planejamento IED'!C:C,"<="&TODAY()) -> 3 | AK26: =SUMIFS('Planejamento IED'!E:E,'Planejamento IED'!A:A,AI26,'Planejamento IED'!F:F,"Embarque",'Planejamento IED'!D:D,"<="&TODAY()) -> 34 | AL26: =COUNTIFS('Planejamento IED'!A:A,'Embarques Vivenciais'!AI26,'Planejamento IED'!F:F,"Embarque") -> 3 | AM26: =SUMIFS('Planejamento IED'!E:E,'Planejamento IED'!A:A,AI26,'Planejamento IED'!F:F,"Embarque") -> 34
B27: 46204 | C27: =B27-1 -> 46203 | D27: =K27+R27+Y27 -> 61 | E27: =COUNTIFS(Equipe!F:F,"Novo",Equipe!D:D,"Técnico")*3 -> 90 | F27: =M27+T27+AA27 -> 641 | G27: =E27*14 -> 1260 | I27: 46204 | J27: =I27-1 -> 46203 | K27: =COUNTIFS('Planejamento IED'!C:C,"<"&J27,'Planejamento IED'!F:F,"Embarque",'Planejamento IED'!H:H,'Embarques Vivenciais'!$I$2,'Planejamento IED'!I:I,"Novo") -> 21 | L27: =COUNTIFS(Equipe!F:F,"Novo",Equipe!D:D,"Técnico",Equipe!E:E,$I$2)*3 -> 24 | M27: =SUMIFS('Planejamento IED'!E:E,'Planejamento IED'!C:C,"<"&J27,'Planejamento IED'!F:F,"Embarque",'Planejamento IED'!H:H,'Embarques Vivenciais'!$I$2,'Planejamento IED'!I:I,"Novo") -> 229 | N27: =L27*14 -> 336 | P27: 46204 | Q27: =P27-1 -> 46203 | R27: =COUNTIFS('Planejamento IED'!C:C,"<"&Q27,'Planejamento IED'!F:F,"Embarque",'Planejamento IED'!H:H,'Embarques Vivenciais'!$P$2,'Planejamento IED'!I:I,"Novo") -> 21 | S27: =COUNTIFS(Equipe!F:F,"Novo",Equipe!D:D,"Técnico",Equipe!E:E,$P$2)*3 -> 24 | T27: =SUMIFS('Planejamento IED'!E:E,'Planejamento IED'!C:C,"<"&Q27,'Planejamento IED'!F:F,"Embarque",'Planejamento IED'!H:H,'Embarques Vivenciais'!$P$2,'Planejamento IED'!I:I,"Novo") -> 233 | U27: =S27*14 -> 336 | W27: 46204 | X27: =W27-1 -> 46203 | Y27: =COUNTIFS('Planejamento IED'!C:C,"<"&X27,'Planejamento IED'!F:F,"Embarque",'Planejamento IED'!H:H,'Embarques Vivenciais'!$W$2,'Planejamento IED'!I:I,"Novo") -> 19 | Z27: =COUNTIFS(Equipe!F:F,"Novo",Equipe!D:D,"Técnico",Equipe!E:E,$W$2)*3 -> 21 | AA27: =SUMIFS('Planejamento IED'!E:E,'Planejamento IED'!C:C,"<"&X27,'Planejamento IED'!F:F,"Embarque",'Planejamento IED'!H:H,'Embarques Vivenciais'!$W$2,'Planejamento IED'!I:I,"Novo") -> 179 | AB27: =Z27*14 -> 294
B28: 46235 | C28: =B28-1 -> 46234 | D28: =K28+R28+Y28 -> 68 | E28: =COUNTIFS(Equipe!F:F,"Novo",Equipe!D:D,"Técnico")*3 -> 90 | F28: =M28+T28+AA28 -> 727 | G28: =E28*14 -> 1260 | I28: 46235 | J28: =I28-1 -> 46234 | K28: =COUNTIFS('Planejamento IED'!C:C,"<"&J28,'Planejamento IED'!F:F,"Embarque",'Planejamento IED'!H:H,'Embarques Vivenciais'!$I$2,'Planejamento IED'!I:I,"Novo") -> 22 | L28: =COUNTIFS(Equipe!F:F,"Novo",Equipe!D:D,"Técnico",Equipe!E:E,$I$2)*3 -> 24 | M28: =SUMIFS('Planejamento IED'!E:E,'Planejamento IED'!C:C,"<"&J28,'Planejamento IED'!F:F,"Embarque",'Planejamento IED'!H:H,'Embarques Vivenciais'!$I$2,'Planejamento IED'!I:I,"Novo") -> 236 | N28: =L28*14 -> 336 | P28: 46235 | Q28: =P28-1 -> 46234 | R28: =COUNTIFS('Planejamento IED'!C:C,"<"&Q28,'Planejamento IED'!F:F,"Embarque",'Planejamento IED'!H:H,'Embarques Vivenciais'!$P$2,'Planejamento IED'!I:I,"Novo") -> 24 | S28: =COUNTIFS(Equipe!F:F,"Novo",Equipe!D:D,"Técnico",Equipe!E:E,$P$2)*3 -> 24 | T28: =SUMIFS('Planejamento IED'!E:E,'Planejamento IED'!C:C,"<"&Q28,'Planejamento IED'!F:F,"Embarque",'Planejamento IED'!H:H,'Embarques Vivenciais'!$P$2,'Planejamento IED'!I:I,"Novo") -> 270 | U28: =S28*14 -> 336 | W28: 46235 | X28: =W28-1 -> 46234 | Y28: =COUNTIFS('Planejamento IED'!C:C,"<"&X28,'Planejamento IED'!F:F,"Embarque",'Planejamento IED'!H:H,'Embarques Vivenciais'!$W$2,'Planejamento IED'!I:I,"Novo") -> 22 | Z28: =COUNTIFS(Equipe!F:F,"Novo",Equipe!D:D,"Técnico",Equipe!E:E,$W$2)*3 -> 21 | AA28: =SUMIFS('Planejamento IED'!E:E,'Planejamento IED'!C:C,"<"&X28,'Planejamento IED'!F:F,"Embarque",'Planejamento IED'!H:H,'Embarques Vivenciais'!$W$2,'Planejamento IED'!I:I,"Novo") -> 221 | AB28: =Z28*14 -> 294
